<mujoco model="bedroom">
  <compiler angle="degree" inertiafromgeom="true"/>
  <option integrator="RK4" timestep="0.01"/>
  
  <asset>
    <material name="wall" rgba="0.9 0.9 0.9 1"/>
    <material name="floor_tile1" rgba="1 1 1 1"/> <!-- 白色 -->
    <material name="floor_tile2" rgba="0.8 0.8 0.8 1"/> <!-- 浅灰色 -->
    <material name="floor_tile3" rgba="0.9 0.9 0.9 1"/> <!-- 中灰色 -->
    <material name="floor_tile4" rgba="0.7 0.7 0.7 1"/> <!-- 深灰色 -->
    <material name="ceiling" rgba="0.95 0.95 0.95 1"/>
    <material name="wood" rgba="0.7 0.5 0.3 1"/>
    <material name="metal" rgba="0.8 0.8 0.8 1"/>
    <material name="fabric" rgba="0.8 0.2 0.2 1"/>
    <material name="plastic" rgba="0.5 0.5 0.5 1"/>
    <material name="window" rgba="0.3 0.6 0.9 0.3"/>
    <material name="light" rgba="1 1 0.9 0.8"/>
    <material name="wardrobe_door" rgba="0.85 0.85 0.85 1"/>
    <material name="wardrobe_inner" rgba="0.9 0.85 0.8 1"/>
    <material name="apple" rgba="0.9 0.1 0.1 1"/>
    <material name="banana" rgba="1 1 0 1"/>
    <material name="orange" rgba="1 0.65 0 1"/>
    <material name="grape" rgba="0.5 0 0.5 1"/>
    <material name="frame" rgba="0.6 0.4 0.2 1"/>
    <material name="picture" rgba="0.2 0.4 0.8 0.9"/>
    <material name="picture_box1" rgba="1 0 0 1"/>
    <material name="picture_box2" rgba="0 1 0 1"/>
    <material name="picture_box3" rgba="0 0 1 1"/>
    <material name="door" rgba="0.6 0.4 0.2 1"/>
  </asset>
  
  <worldbody>
    <!-- 相机视角 -->
    <camera name="main_camera" pos="5 5 3" fovy="60"/>
    
    <!-- 光照设置 -->
    <!-- 方向光（模拟太阳光） -->
    <light diffuse="1 1 1" pos="5 -5 5" dir="-1 1 -1"/>
    <!-- 点光源1（天花板灯） -->
    <light diffuse="1 1 0.9" pos="0 0 2.3"/>
    <!-- 点光源2（落地灯） -->
    <light diffuse="1 1 0.9" pos="3 2 1.9"/>
    <!-- 点光源3（小桌子台灯） -->
    <light diffuse="1 1 0.9" pos="-3 1 1.05"/>
    <!-- 点光源4（餐桌台灯） -->
    <light diffuse="1 1 0.9" pos="0.5 2 1.05"/>
    
    <!-- 地板：拼色方块地板砖 -->
    <!-- 创建10x10的地板砖网格，使用四种颜色的拼色图案 -->
    <!-- 第一行 -->
    <geom name="tile_0_0" type="box" size="0.5 0.5 0.05" pos="-4.5 -4.5 0" material="floor_tile1"/>
    <geom name="tile_1_0" type="box" size="0.5 0.5 0.05" pos="-3.5 -4.5 0" material="floor_tile2"/>
    <geom name="tile_2_0" type="box" size="0.5 0.5 0.05" pos="-2.5 -4.5 0" material="floor_tile3"/>
    <geom name="tile_3_0" type="box" size="0.5 0.5 0.05" pos="-1.5 -4.5 0" material="floor_tile4"/>
    <geom name="tile_4_0" type="box" size="0.5 0.5 0.05" pos="-0.5 -4.5 0" material="floor_tile1"/>
    <geom name="tile_5_0" type="box" size="0.5 0.5 0.05" pos="0.5 -4.5 0" material="floor_tile2"/>
    <geom name="tile_6_0" type="box" size="0.5 0.5 0.05" pos="1.5 -4.5 0" material="floor_tile3"/>
    <geom name="tile_7_0" type="box" size="0.5 0.5 0.05" pos="2.5 -4.5 0" material="floor_tile4"/>
    <geom name="tile_8_0" type="box" size="0.5 0.5 0.05" pos="3.5 -4.5 0" material="floor_tile1"/>
    <geom name="tile_9_0" type="box" size="0.5 0.5 0.05" pos="4.5 -4.5 0" material="floor_tile2"/>
    <!-- 第二行 -->
    <geom name="tile_0_1" type="box" size="0.5 0.5 0.05" pos="-4.5 -3.5 0" material="floor_tile2"/>
    <geom name="tile_1_1" type="box" size="0.5 0.5 0.05" pos="-3.5 -3.5 0" material="floor_tile3"/>
    <geom name="tile_2_1" type="box" size="0.5 0.5 0.05" pos="-2.5 -3.5 0" material="floor_tile4"/>
    <geom name="tile_3_1" type="box" size="0.5 0.5 0.05" pos="-1.5 -3.5 0" material="floor_tile1"/>
    <geom name="tile_4_1" type="box" size="0.5 0.5 0.05" pos="-0.5 -3.5 0" material="floor_tile2"/>
    <geom name="tile_5_1" type="box" size="0.5 0.5 0.05" pos="0.5 -3.5 0" material="floor_tile3"/>
    <geom name="tile_6_1" type="box" size="0.5 0.5 0.05" pos="1.5 -3.5 0" material="floor_tile4"/>
    <geom name="tile_7_1" type="box" size="0.5 0.5 0.05" pos="2.5 -3.5 0" material="floor_tile1"/>
    <geom name="tile_8_1" type="box" size="0.5 0.5 0.05" pos="3.5 -3.5 0" material="floor_tile2"/>
    <geom name="tile_9_1" type="box" size="0.5 0.5 0.05" pos="4.5 -3.5 0" material="floor_tile3"/>
    <!-- 第三行 -->
    <geom name="tile_0_2" type="box" size="0.5 0.5 0.05" pos="-4.5 -2.5 0" material="floor_tile3"/>
    <geom name="tile_1_2" type="box" size="0.5 0.5 0.05" pos="-3.5 -2.5 0" material="floor_tile4"/>
    <geom name="tile_2_2" type="box" size="0.5 0.5 0.05" pos="-2.5 -2.5 0" material="floor_tile1"/>
    <geom name="tile_3_2" type="box" size="0.5 0.5 0.05" pos="-1.5 -2.5 0" material="floor_tile2"/>
    <geom name="tile_4_2" type="box" size="0.5 0.5 0.05" pos="-0.5 -2.5 0" material="floor_tile3"/>
    <geom name="tile_5_2" type="box" size="0.5 0.5 0.05" pos="0.5 -2.5 0" material="floor_tile4"/>
    <geom name="tile_6_2" type="box" size="0.5 0.5 0.05" pos="1.5 -2.5 0" material="floor_tile1"/>
    <geom name="tile_7_2" type="box" size="0.5 0.5 0.05" pos="2.5 -2.5 0" material="floor_tile2"/>
    <geom name="tile_8_2" type="box" size="0.5 0.5 0.05" pos="3.5 -2.5 0" material="floor_tile3"/>
    <geom name="tile_9_2" type="box" size="0.5 0.5 0.05" pos="4.5 -2.5 0" material="floor_tile4"/>
    <!-- 第四行 -->
    <geom name="tile_0_3" type="box" size="0.5 0.5 0.05" pos="-4.5 -1.5 0" material="floor_tile4"/>
    <geom name="tile_1_3" type="box" size="0.5 0.5 0.05" pos="-3.5 -1.5 0" material="floor_tile1"/>
    <geom name="tile_2_3" type="box" size="0.5 0.5 0.05" pos="-2.5 -1.5 0" material="floor_tile2"/>
    <geom name="tile_3_3" type="box" size="0.5 0.5 0.05" pos="-1.5 -1.5 0" material="floor_tile3"/>
    <geom name="tile_4_3" type="box" size="0.5 0.5 0.05" pos="-0.5 -1.5 0" material="floor_tile4"/>
    <geom name="tile_5_3" type="box" size="0.5 0.5 0.05" pos="0.5 -1.5 0" material="floor_tile1"/>
    <geom name="tile_6_3" type="box" size="0.5 0.5 0.05" pos="1.5 -1.5 0" material="floor_tile2"/>
    <geom name="tile_7_3" type="box" size="0.5 0.5 0.05" pos="2.5 -1.5 0" material="floor_tile3"/>
    <geom name="tile_8_3" type="box" size="0.5 0.5 0.05" pos="3.5 -1.5 0" material="floor_tile4"/>
    <geom name="tile_9_3" type="box" size="0.5 0.5 0.05" pos="4.5 -1.5 0" material="floor_tile1"/>
    <!-- 第五行 -->
    <geom name="tile_0_4" type="box" size="0.5 0.5 0.05" pos="-4.5 -0.5 0" material="floor_tile1"/>
    <geom name="tile_1_4" type="box" size="0.5 0.5 0.05" pos="-3.5 -0.5 0" material="floor_tile2"/>
    <geom name="tile_2_4" type="box" size="0.5 0.5 0.05" pos="-2.5 -0.5 0" material="floor_tile3"/>
    <geom name="tile_3_4" type="box" size="0.5 0.5 0.05" pos="-1.5 -0.5 0" material="floor_tile4"/>
    <geom name="tile_4_4" type="box" size="0.5 0.5 0.05" pos="-0.5 -0.5 0" material="floor_tile1"/>
    <geom name="tile_5_4" type="box" size="0.5 0.5 0.05" pos="0.5 -0.5 0" material="floor_tile2"/>
    <geom name="tile_6_4" type="box" size="0.5 0.5 0.05" pos="1.5 -0.5 0" material="floor_tile3"/>
    <geom name="tile_7_4" type="box" size="0.5 0.5 0.05" pos="2.5 -0.5 0" material="floor_tile4"/>
    <geom name="tile_8_4" type="box" size="0.5 0.5 0.05" pos="3.5 -0.5 0" material="floor_tile1"/>
    <geom name="tile_9_4" type="box" size="0.5 0.5 0.05" pos="4.5 -0.5 0" material="floor_tile2"/>
    <!-- 第六行 -->
    <geom name="tile_0_5" type="box" size="0.5 0.5 0.05" pos="-4.5 0.5 0" material="floor_tile2"/>
    <geom name="tile_1_5" type="box" size="0.5 0.5 0.05" pos="-3.5 0.5 0" material="floor_tile3"/>
    <geom name="tile_2_5" type="box" size="0.5 0.5 0.05" pos="-2.5 0.5 0" material="floor_tile4"/>
    <geom name="tile_3_5" type="box" size="0.5 0.5 0.05" pos="-1.5 0.5 0" material="floor_tile1"/>
    <geom name="tile_4_5" type="box" size="0.5 0.5 0.05" pos="-0.5 0.5 0" material="floor_tile2"/>
    <geom name="tile_5_5" type="box" size="0.5 0.5 0.05" pos="0.5 0.5 0" material="floor_tile3"/>
    <geom name="tile_6_5" type="box" size="0.5 0.5 0.05" pos="1.5 0.5 0" material="floor_tile4"/>
    <geom name="tile_7_5" type="box" size="0.5 0.5 0.05" pos="2.5 0.5 0" material="floor_tile1"/>
    <geom name="tile_8_5" type="box" size="0.5 0.5 0.05" pos="3.5 0.5 0" material="floor_tile2"/>
    <geom name="tile_9_5" type="box" size="0.5 0.5 0.05" pos="4.5 0.5 0" material="floor_tile3"/>
    <!-- 第七行 -->
    <geom name="tile_0_6" type="box" size="0.5 0.5 0.05" pos="-4.5 1.5 0" material="floor_tile3"/>
    <geom name="tile_1_6" type="box" size="0.5 0.5 0.05" pos="-3.5 1.5 0" material="floor_tile4"/>
    <geom name="tile_2_6" type="box" size="0.5 0.5 0.05" pos="-2.5 1.5 0" material="floor_tile1"/>
    <geom name="tile_3_6" type="box" size="0.5 0.5 0.05" pos="-1.5 1.5 0" material="floor_tile2"/>
    <geom name="tile_4_6" type="box" size="0.5 0.5 0.05" pos="-0.5 1.5 0" material="floor_tile3"/>
    <geom name="tile_5_6" type="box" size="0.5 0.5 0.05" pos="0.5 1.5 0" material="floor_tile4"/>
    <geom name="tile_6_6" type="box" size="0.5 0.5 0.05" pos="1.5 1.5 0" material="floor_tile1"/>
    <geom name="tile_7_6" type="box" size="0.5 0.5 0.05" pos="2.5 1.5 0" material="floor_tile2"/>
    <geom name="tile_8_6" type="box" size="0.5 0.5 0.05" pos="3.5 1.5 0" material="floor_tile3"/>
    <geom name="tile_9_6" type="box" size="0.5 0.5 0.05" pos="4.5 1.5 0" material="floor_tile4"/>
    <!-- 第八行 -->
    <geom name="tile_0_7" type="box" size="0.5 0.5 0.05" pos="-4.5 2.5 0" material="floor_tile4"/>
    <geom name="tile_1_7" type="box" size="0.5 0.5 0.05" pos="-3.5 2.5 0" material="floor_tile1"/>
    <geom name="tile_2_7" type="box" size="0.5 0.5 0.05" pos="-2.5 2.5 0" material="floor_tile2"/>
    <geom name="tile_3_7" type="box" size="0.5 0.5 0.05" pos="-1.5 2.5 0" material="floor_tile3"/>
    <geom name="tile_4_7" type="box" size="0.5 0.5 0.05" pos="-0.5 2.5 0" material="floor_tile4"/>
    <geom name="tile_5_7" type="box" size="0.5 0.5 0.05" pos="0.5 2.5 0" material="floor_tile1"/>
    <geom name="tile_6_7" type="box" size="0.5 0.5 0.05" pos="1.5 2.5 0" material="floor_tile2"/>
    <geom name="tile_7_7" type="box" size="0.5 0.5 0.05" pos="2.5 2.5 0" material="floor_tile3"/>
    <geom name="tile_8_7" type="box" size="0.5 0.5 0.05" pos="3.5 2.5 0" material="floor_tile4"/>
    <geom name="tile_9_7" type="box" size="0.5 0.5 0.05" pos="4.5 2.5 0" material="floor_tile1"/>
    <!-- 第九行 -->
    <geom name="tile_0_8" type="box" size="0.5 0.5 0.05" pos="-4.5 3.5 0" material="floor_tile1"/>
    <geom name="tile_1_8" type="box" size="0.5 0.5 0.05" pos="-3.5 3.5 0" material="floor_tile2"/>
    <geom name="tile_2_8" type="box" size="0.5 0.5 0.05" pos="-2.5 3.5 0" material="floor_tile3"/>
    <geom name="tile_3_8" type="box" size="0.5 0.5 0.05" pos="-1.5 3.5 0" material="floor_tile4"/>
    <geom name="tile_4_8" type="box" size="0.5 0.5 0.05" pos="-0.5 3.5 0" material="floor_tile1"/>
    <geom name="tile_5_8" type="box" size="0.5 0.5 0.05" pos="0.5 3.5 0" material="floor_tile2"/>
    <geom name="tile_6_8" type="box" size="0.5 0.5 0.05" pos="1.5 3.5 0" material="floor_tile3"/>
    <geom name="tile_7_8" type="box" size="0.5 0.5 0.05" pos="2.5 3.5 0" material="floor_tile4"/>
    <geom name="tile_8_8" type="box" size="0.5 0.5 0.05" pos="3.5 3.5 0" material="floor_tile1"/>
    <geom name="tile_9_8" type="box" size="0.5 0.5 0.05" pos="4.5 3.5 0" material="floor_tile2"/>
    <!-- 第十行 -->
    <geom name="tile_0_9" type="box" size="0.5 0.5 0.05" pos="-4.5 4.5 0" material="floor_tile2"/>
    <geom name="tile_1_9" type="box" size="0.5 0.5 0.05" pos="-3.5 4.5 0" material="floor_tile3"/>
    <geom name="tile_2_9" type="box" size="0.5 0.5 0.05" pos="-2.5 4.5 0" material="floor_tile4"/>
    <geom name="tile_3_9" type="box" size="0.5 0.5 0.05" pos="-1.5 4.5 0" material="floor_tile1"/>
    <geom name="tile_4_9" type="box" size="0.5 0.5 0.05" pos="-0.5 4.5 0" material="floor_tile2"/>
    <geom name="tile_5_9" type="box" size="0.5 0.5 0.05" pos="0.5 4.5 0" material="floor_tile3"/>
    <geom name="tile_6_9" type="box" size="0.5 0.5 0.05" pos="1.5 4.5 0" material="floor_tile4"/>
    <geom name="tile_7_9" type="box" size="0.5 0.5 0.05" pos="2.5 4.5 0" material="floor_tile1"/>
    <geom name="tile_8_9" type="box" size="0.5 0.5 0.05" pos="3.5 4.5 0" material="floor_tile2"/>
    <geom name="tile_9_9" type="box" size="0.5 0.5 0.05" pos="4.5 4.5 0" material="floor_tile3"/>
    
    <!-- 墙壁 -->
    <geom name="wall_back" type="box" size="5 0.1 2.5" pos="0 -5 1.25" material="wall"/>
    <!-- 正面墙壁（分成左右两部分，中间留出门的空间） -->
    <geom name="wall_front_left" type="box" size="4.4 0.1 2.5" pos="-2.2 5 1.25" material="wall"/>
    <geom name="wall_front_right" type="box" size="4.4 0.1 2.5" pos="2.2 5 1.25" material="wall"/>
    <geom name="wall_left" type="box" size="0.1 5 2.5" pos="-5 0 1.25" material="wall"/>
    <geom name="wall_right" type="box" size="0.1 5 2.5" pos="5 0 1.25" material="wall"/>
    
    <!-- 门：带铰链的可开关门 -->
    <body name="door" pos="0 5 1">
      <!-- 门铰链 -->
      <joint name="door_hinge" type="hinge" axis="0 0 1" pos="-0.6 0 0" range="-120 0"/>
      <!-- 门本身 -->
      <geom name="door_panel" type="box" size="0.58 0.02 1.9" pos="0 0 1" material="door"/>
    </body>
    
    <!-- 窗户 -->
    <geom name="window_front" type="box" size="1.5 0.1 1" pos="0 5 1.5" material="window"/>
    
    <!-- 相框：背面墙壁 -->
    <body name="picture_frame" pos="0 -5 2">
      <!-- 相框外框 -->
      <geom name="frame_outer" type="box" size="0.6 0.03 0.8" pos="0 0 0.01" material="frame"/>
      <!-- 相框内框 -->
      <geom name="frame_inner" type="box" size="0.55 0.01 0.75" pos="0 0 0.02" material="picture"/>
      <!-- 彩色方框图片 -->
      <geom name="picture_box_red" type="box" size="0.15 0.005 0.15" pos="-0.2 0 0.03" material="picture_box1"/>
      <geom name="picture_box_green" type="box" size="0.15 0.005 0.15" pos="0.2 0 0.03" material="picture_box2"/>
      <geom name="picture_box_blue" type="box" size="0.15 0.005 0.15" pos="0 0.3 0.03" material="picture_box3"/>
      <geom name="picture_box_red2" type="box" size="0.1 0.005 0.1" pos="0.15 -0.2 0.03" material="picture_box1"/>
      <geom name="picture_box_green2" type="box" size="0.1 0.005 0.1" pos="-0.15 -0.2 0.03" material="picture_box2"/>
    </body>
    
    <!-- 天花板 -->
    <geom name="ceiling" type="plane" size="5 5 0.1" pos="0 0 2.5" material="ceiling" euler="180 0 0"/>
    
    <!-- 床 -->
    <body name="bed" pos="0 -2 0">
      <!-- 床架 -->
      <geom name="bed_frame" type="box" size="2 1 0.1" pos="0 0 0.3" material="wood"/>
      <geom name="bed_leg1" type="cylinder" size="0.05 0.3" pos="-1.5 -0.8 0.15" material="wood"/>
      <geom name="bed_leg2" type="cylinder" size="0.05 0.3" pos="1.5 -0.8 0.15" material="wood"/>
      <geom name="bed_leg3" type="cylinder" size="0.05 0.3" pos="-1.5 0.8 0.15" material="wood"/>
      <geom name="bed_leg4" type="cylinder" size="0.05 0.3" pos="1.5 0.8 0.15" material="wood"/>
      
      <!-- 床垫 -->
      <geom name="mattress" type="box" size="1.9 0.9 0.2" pos="0 0 0.55" material="fabric"/>
      
      <!-- 枕头 -->
      <geom name="pillow" type="box" size="0.5 0.3 0.1" pos="1.2 0 0.7" material="fabric"/>
    </body>
    
    <!-- 床头柜和台灯 -->
    <body name="nightstand" pos="2 -2 0">
      <geom name="nightstand_top" type="box" size="0.3 0.3 0.05" pos="0 0 0.4" material="wood"/>
      <geom name="nightstand_body" type="box" size="0.25 0.25 0.35" pos="0 0 0.2" material="wood"/>
      
      <!-- 台灯 -->
      <body name="lamp" pos="0 0 0.4">
        <geom name="lamp_base" type="cylinder" size="0.15 0.05" pos="0 0 0.05" material="metal"/>
        <geom name="lamp_pole" type="cylinder" size="0.02 0.3" pos="0 0 0.25" material="metal"/>
        <geom name="lamp_shade" type="cylinder" size="0.15 0.15" pos="0 0 0.5" material="plastic" euler="90 0 0"/>
      </body>
      
      <!-- 书籍 -->
      <geom name="book1" type="box" size="0.15 0.02 0.2" pos="-0.1 0.1 0.45" material="plastic"/>
      <geom name="book2" type="box" size="0.15 0.02 0.2" pos="-0.1 0 0.48" material="plastic"/>
      <geom name="book3" type="box" size="0.15 0.02 0.2" pos="-0.1 -0.1 0.51" material="plastic"/>
    </body>
    
    <!-- 小桌子和画册 -->
    <body name="table" pos="-3 1 0">
      <geom name="table_top" type="box" size="0.4 0.4 0.05" pos="0 0 0.6" material="wood"/>
      <geom name="table_leg1" type="cylinder" size="0.04 0.3" pos="-0.3 -0.3 0.3" material="wood"/>
      <geom name="table_leg2" type="cylinder" size="0.04 0.3" pos="0.3 -0.3 0.3" material="wood"/>
      <geom name="table_leg3" type="cylinder" size="0.04 0.3" pos="-0.3 0.3 0.3" material="wood"/>
      <geom name="table_leg4" type="cylinder" size="0.04 0.3" pos="0.3 0.3 0.3" material="wood"/>
      
      <!-- 台灯 -->
      <body name="table_lamp" pos="0 0 0.6">
        <geom name="table_lamp_base" type="cylinder" size="0.1 0.05" pos="0 0 0.05" material="metal"/>
        <geom name="table_lamp_pole" type="cylinder" size="0.02 0.3" pos="0 0 0.25" material="metal"/>
        <geom name="table_lamp_shade" type="cylinder" size="0.12 0.12" pos="0 0 0.45" material="light" euler="90 0 0"/>
      </body>
      
      <!-- 画册 -->
      <geom name="album1" type="box" size="0.2 0.03 0.25" pos="0 0 0.65" material="plastic"/>
      <geom name="album2" type="box" size="0.2 0.03 0.25" pos="0 0.15 0.65" material="plastic"/>
      <geom name="album3" type="box" size="0.2 0.03 0.25" pos="0.15 0 0.65" material="plastic"/>
    </body>
    
    <!-- 落地灯 -->
    <body name="floor_lamp" pos="3 2 0">
      <geom name="floor_lamp_base" type="cylinder" size="0.2 0.05" pos="0 0 0.05" material="metal"/>
      <geom name="floor_lamp_pole" type="cylinder" size="0.03 1.5" pos="0 0 0.8" material="metal"/>
      <geom name="floor_lamp_shade" type="cylinder" size="0.25 0.25" pos="0 0 1.9" material="light" euler="90 0 0"/>
    </body>
    
    <!-- 天花板吊灯 -->
    <body name="ceiling_light" pos="0 0 2.5">
      <geom name="ceiling_light_base" type="cylinder" size="0.1 0.05" pos="0 0 -0.05" material="metal"/>
      <geom name="ceiling_light_chain" type="cylinder" size="0.01 0.2" pos="0 0 -0.2" material="metal"/>
      <geom name="ceiling_light_shade" type="cylinder" size="0.2 0.15" pos="0 0 -0.4" material="light" euler="90 0 0"/>
    </body>
    
    <!-- 衣柜1：左侧墙壁 -->
    <body name="wardrobe1" pos="-4 0 1">
      <geom name="wardrobe1_body" type="box" size="0.5 0.6 1.5" pos="0 0 1" material="wood"/>
      <geom name="wardrobe1_door1" type="box" size="0.45 0.55 0.02" pos="-0.25 0 1" material="wardrobe_door"/>
      <geom name="wardrobe1_door2" type="box" size="0.45 0.55 0.02" pos="0.25 0 1" material="wardrobe_door"/>
      <geom name="wardrobe1_shelf1" type="box" size="0.4 0.5 0.02" pos="0 0 1.5" material="wardrobe_inner"/>
      <geom name="wardrobe1_shelf2" type="box" size="0.4 0.5 0.02" pos="0 0 0.8" material="wardrobe_inner"/>
    </body>
    
    <!-- 衣柜2：右侧墙壁 -->
    <body name="wardrobe2" pos="4 0 1">
      <geom name="wardrobe2_body" type="box" size="0.5 0.6 1.5" pos="0 0 1" material="wood"/>
      <geom name="wardrobe2_door1" type="box" size="0.45 0.55 0.02" pos="-0.25 0 1" material="wardrobe_door"/>
      <geom name="wardrobe2_door2" type="box" size="0.45 0.55 0.02" pos="0.25 0 1" material="wardrobe_door"/>
      <geom name="wardrobe2_shelf1" type="box" size="0.4 0.5 0.02" pos="0 0 1.5" material="wardrobe_inner"/>
      <geom name="wardrobe2_shelf2" type="box" size="0.4 0.5 0.02" pos="0 0 0.8" material="wardrobe_inner"/>
    </body>
    
    <!-- 新桌子：中央偏前 -->
    <body name="dining_table" pos="0 2 0">
      <geom name="dining_table_top" type="cylinder" size="0.8 0.05" pos="0 0 0.6" material="wood"/>
      <geom name="dining_table_leg1" type="cylinder" size="0.05 0.3" pos="-0.5 0.5 0.3" material="wood"/>
      <geom name="dining_table_leg2" type="cylinder" size="0.05 0.3" pos="0.5 0.5 0.3" material="wood"/>
      <geom name="dining_table_leg3" type="cylinder" size="0.05 0.3" pos="-0.5 -0.5 0.3" material="wood"/>
      <geom name="dining_table_leg4" type="cylinder" size="0.05 0.3" pos="0.5 -0.5 0.3" material="wood"/>
      
      <!-- 台灯 -->
      <body name="dining_table_lamp" pos="0.5 0 0.6">
        <geom name="dining_lamp_base" type="cylinder" size="0.1 0.05" pos="0 0 0.05" material="metal"/>
        <geom name="dining_lamp_pole" type="cylinder" size="0.02 0.3" pos="0 0 0.25" material="metal"/>
        <geom name="dining_lamp_shade" type="cylinder" size="0.12 0.12" pos="0 0 0.45" material="light" euler="90 0 0"/>
      </body>
      
      <!-- 水果 -->
      <!-- 苹果 -->
      <geom name="apple1" type="sphere" size="0.08" pos="-0.3 0.2 0.68" material="apple"/>
      <geom name="apple2" type="sphere" size="0.08" pos="-0.1 0.25 0.68" material="apple"/>
      <geom name="apple3" type="sphere" size="0.08" pos="0.1 0.2 0.68" material="apple"/>
      
      <!-- 香蕉 -->
      <geom name="banana1" type="capsule" size="0.06 0.12" pos="-0.2 -0.2 0.68" material="banana" euler="0 30 0"/>
      <geom name="banana2" type="capsule" size="0.06 0.12" pos="0 -0.2 0.68" material="banana" euler="0 0 0"/>
      <geom name="banana3" type="capsule" size="0.06 0.12" pos="0.2 -0.2 0.68" material="banana" euler="0 -30 0"/>
      
      <!-- 橙子 -->
      <geom name="orange1" type="sphere" size="0.09" pos="0.3 -0.1 0.68" material="orange"/>
      <geom name="orange2" type="sphere" size="0.09" pos="0.4 0.1 0.68" material="orange"/>
      
      <!-- 葡萄 -->
      <geom name="grape1" type="sphere" size="0.04" pos="-0.35 -0.1 0.68" material="grape"/>
      <geom name="grape2" type="sphere" size="0.04" pos="-0.3 -0.05 0.72" material="grape"/>
      <geom name="grape3" type="sphere" size="0.04" pos="-0.25 -0.1 0.68" material="grape"/>
      <geom name="grape4" type="sphere" size="0.04" pos="-0.3 -0.15 0.72" material="grape"/>
    </body>
    
    <!-- 机器人 -->
    <body name="robot_base" pos="0 0 0">
      <!-- 移动关节 -->
      <joint name="robot_x_joint" type="slide" axis="1 0 0"/>
      <joint name="robot_y_joint" type="slide" axis="0 1 0"/>
      <joint name="robot_rot_joint" type="hinge" axis="0 0 1"/>
      
      <!-- 机器人主体 -->
      <body name="robot" pos="0 0 0.5">
        <!-- 底盘 -->
        <geom name="chassis" type="box" size="0.4 0.4 0.2" pos="0 0 0" material="metal"/>
        
        <!-- 球形轮子 -->
        <geom name="wheel_front_left" type="sphere" size="0.15" pos="-0.3 -0.3 -0.2" material="metal"/>
        <geom name="wheel_front_right" type="sphere" size="0.15" pos="0.3 -0.3 -0.2" material="metal"/>
        <geom name="wheel_back_left" type="sphere" size="0.15" pos="-0.3 0.3 -0.2" material="metal"/>
        <geom name="wheel_back_right" type="sphere" size="0.15" pos="0.3 0.3 -0.2" material="metal"/>
      
        <!-- 头部 -->
        <body name="head" pos="0 0 0.4">
          <geom name="head_geom" type="sphere" size="0.15" material="plastic"/>
        </body>
      
        <!-- 左臂 -->
        <body name="left_shoulder" pos="-0.4 0 0.2">
          <joint name="left_shoulder_joint" type="ball"/>
          <geom name="left_shoulder_geom" type="cylinder" size="0.08 0.1" pos="-0.1 0 0" material="metal" euler="0 90 0"/>
          
          <body name="left_elbow" pos="-0.2 0 0">
            <joint name="left_elbow_joint" type="hinge" axis="0 1 0" range="-90 90"/>
            <geom name="left_upper_arm" type="cylinder" size="0.05 0.2" pos="-0.2 0 0" material="metal" euler="0 90 0"/>
            
            <body name="left_wrist" pos="-0.4 0 0">
              <joint name="left_wrist_joint" type="hinge" axis="0 1 0" range="-90 90"/>
              <geom name="left_lower_arm" type="cylinder" size="0.03 0.15" pos="-0.15 0 0" material="metal" euler="0 90 0"/>
              <geom name="left_hand" type="sphere" size="0.05" pos="-0.3 0 0" material="plastic"/>
            </body>
          </body>
        </body>
      
        <!-- 右臂 -->
        <body name="right_shoulder" pos="0.4 0 0.2">
          <joint name="right_shoulder_joint" type="ball"/>
          <geom name="right_shoulder_geom" type="cylinder" size="0.08 0.1" pos="0.1 0 0" material="metal" euler="0 90 0"/>
          
          <body name="right_elbow" pos="0.2 0 0">
            <joint name="right_elbow_joint" type="hinge" axis="0 1 0" range="-90 90"/>
            <geom name="right_upper_arm" type="cylinder" size="0.05 0.2" pos="0.2 0 0" material="metal" euler="0 90 0"/>
            
            <body name="right_wrist" pos="0.4 0 0">
              <joint name="right_wrist_joint" type="hinge" axis="0 1 0" range="-90 90"/>
              <geom name="right_lower_arm" type="cylinder" size="0.03 0.15" pos="0.15 0 0" material="metal" euler="0 90 0"/>
              <geom name="right_hand" type="sphere" size="0.05" pos="0.3 0 0" material="plastic"/>
            </body>
          </body>
        </body>
      </body>
    </body>
  </worldbody>
  
  <actuator>
    <!-- 机器人手臂关节控制器 -->
    <motor name="left_shoulder_motor" joint="left_shoulder_joint" gear="5"/>
    <motor name="left_elbow_motor" joint="left_elbow_joint" gear="5"/>
    <motor name="left_wrist_motor" joint="left_wrist_joint" gear="5"/>
    
    <motor name="right_shoulder_motor" joint="right_shoulder_joint" gear="5"/>
    <motor name="right_elbow_motor" joint="right_elbow_joint" gear="5"/>
    <motor name="right_wrist_motor" joint="right_wrist_joint" gear="5"/>
    
    <!-- 机器人行走控制器 -->
    <motor name="robot_x_motor" joint="robot_x_joint" gear="100" ctrllimited="true" ctrlrange="-1 1"/>
    <motor name="robot_y_motor" joint="robot_y_joint" gear="100" ctrllimited="true" ctrlrange="-1 1"/>
    <motor name="robot_rot_motor" joint="robot_rot_joint" gear="100" ctrllimited="true" ctrlrange="-1 1"/>
    
    <!-- 门控制器 -->
    <motor name="door_motor" joint="door_hinge" gear="50" ctrllimited="true" ctrlrange="-1 1"/>
  </actuator>
</mujoco>